Workbook
Name Status: Projects!$P$6

Sheet Projects
R1: Contracted
R2: Checking
R3: Not contracted
R4: #N/A
A5: Project | B5: S/N | C5: PO Number | D5: Delivery Stage | E5: PO Name | F5: PO Name [Standardized] | G5: Account Code | H5: Category | I5: Status | J5: PO Issue Date | K5: Req. Delivery Date | L5: Vessel Category | M5: Po Value | N5: Po Currency | O5: Supplier Name | P5: Contract Status
A6: Glovis Luminous | C6: GLUM-60015/26-1 | D6: =IF(OR(ISNUMBER(SEARCH("Pre Delivery",E6)),ISNUMBER(SEARCH("Pre-Delivery",E6)),ISNUMBER(SEARCH("Predelivery",E6)),ISNUMBER(SEARCH("PD -",E6)),ISNUMBER(SEARCH("PD Lubes",E6))),"Pre-Delivery","") -> Pre-Delivery | E6: PD - RSC Envirologic | F6: Lubricants | H6: Spares | I6: PO Created | L6: PCTC | M6: #N/A | N6: #N/A | O6: #N/A | P6: #N/A
A7: Glovis Luminous | C7: GLUM-60003/26-1 | D7: =IF(OR(ISNUMBER(SEARCH("Pre Delivery",E7)),ISNUMBER(SEARCH("Pre-Delivery",E7)),ISNUMBER(SEARCH("Predelivery",E7)),ISNUMBER(SEARCH("PD -",E7)),ISNUMBER(SEARCH("PD Lubes",E7))),"Pre-Delivery","") | E7: FS-ITBP -luminous | F7: IT Equipment - ITBP | H7: Spares | I7: Pending Delivery | J7: 46055 | L7: PCTC | M7: #N/A | N7: #N/A | O7: #N/A | P7: #N/A
A8: Glovis Luminous | C8: GLUM-MVSP-60002/26-1 | D8: =IF(OR(ISNUMBER(SEARCH("Pre Delivery",E8)),ISNUMBER(SEARCH("Pre-Delivery",E8)),ISNUMBER(SEARCH("Predelivery",E8)),ISNUMBER(SEARCH("PD -",E8)),ISNUMBER(SEARCH("PD Lubes",E8))),"Pre-Delivery","") | E8: FS-X10-SILVERPEAK | F8: IT Equipment - X10 System | H8: Spares | I8: Pending Supplier Confirmation | J8: 46101 | L8: PCTC | M8: #N/A | N8: #N/A | O8: #N/A | P8: #N/A
A9: Glovis Luminous | C9: GLUM-60024/26-1 | D9: =IF(OR(ISNUMBER(SEARCH("Pre Delivery",E9)),ISNUMBER(SEARCH("Pre-Delivery",E9)),ISNUMBER(SEARCH("Predelivery",E9)),ISNUMBER(SEARCH("PD -",E9)),ISNUMBER(SEARCH("PD Lubes",E9))),"Pre-Delivery","") | E9: Service: LNG OPERATION MANUAL Development | F9: LNG Operation Manual | H9: Spares | I9: PO Created | L9: PCTC | M9: #N/A | N9: #N/A | O9: #N/A | P9: #N/A
A10: Glovis Luminous | C10: GLUM-60006/26-1 | D10: =IF(OR(ISNUMBER(SEARCH("Pre Delivery",E10)),ISNUMBER(SEARCH("Pre-Delivery",E10)),ISNUMBER(SEARCH("Predelivery",E10)),ISNUMBER(SEARCH("PD -",E10)),ISNUMBER(SEARCH("PD Lubes",E10))),"Pre-Delivery","") | E10: Shipyard Extra Buyers Supply - Tripods and Spray Pipes | F10: Tripods & Spray Pipes | H10: Spares | I10: Pending Delivery | J10: 46091 | L10: PCTC | M10: #N/A | N10: #N/A | O10: #N/A | P10: #N/A
A11: Glovis Luminous | C11: GLUM-60019/26-1 | D11: =IF(OR(ISNUMBER(SEARCH("Pre Delivery",E11)),ISNUMBER(SEARCH("Pre-Delivery",E11)),ISNUMBER(SEARCH("Predelivery",E11)),ISNUMBER(SEARCH("PD -",E11)),ISNUMBER(SEARCH("PD Lubes",E11))),"Pre-Delivery","") | E11: Shipyard Extra (buyer Supply) - QCDC -GSI | F11: QCDC | H11: Spares | I11: Pending Supplier Confirmation | J11: 46101 | L11: PCTC | M11: #N/A | N11: #N/A | O11: #N/A | P11: #N/A
A12: Glovis Luminous | C12: GLUM-60016/26-1 | D12: =IF(OR(ISNUMBER(SEARCH("Pre Delivery",E12)),ISNUMBER(SEARCH("Pre-Delivery",E12)),ISNUMBER(SEARCH("Predelivery",E12)),ISNUMBER(SEARCH("PD -",E12)),ISNUMBER(SEARCH("PD Lubes",E12))),"Pre-Delivery","") | E12: Reliabiltiy Spares - Gas Detection System | F12: Gas Detection System | H12: Spares | I12: Pending Delivery | J12: 46087 | L12: PCTC | M12: #N/A | N12: #N/A | O12: #N/A | P12: #N/A
A13: Glovis Luminous | C13: GLUM-60008/26-1 | D13: =IF(OR(ISNUMBER(SEARCH("Pre Delivery",E13)),ISNUMBER(SEARCH("Pre-Delivery",E13)),ISNUMBER(SEARCH("Predelivery",E13)),ISNUMBER(SEARCH("PD -",E13)),ISNUMBER(SEARCH("PD Lubes",E13))),"Pre-Delivery","") | E13: Shipyard Extra Buyers Supply - Hinas SVM SEASPAN 10.8K PCTC | F13: Navigation - HiNAS SVM | H13: Spares | I13: Pending Supplier Confirmation | J13: 46070 | L13: PCTC | M13: #N/A | N13: #N/A | O13: #N/A | P13: #N/A
A14: Glovis Luminous | C14: GLUM-60010/26-1 | D14: =IF(OR(ISNUMBER(SEARCH("Pre Delivery",E14)),ISNUMBER(SEARCH("Pre-Delivery",E14)),ISNUMBER(SEARCH("Predelivery",E14)),ISNUMBER(SEARCH("PD -",E14)),ISNUMBER(SEARCH("PD Lubes",E14))),"Pre-Delivery","") | E14: FS-ITBP Additional Item | F14: IT Equipment - ITBP Additional Items | H14: Spares | I14: Pending Delivery | J14: 46072 | L14: PCTC | M14: #N/A | N14: #N/A | O14: #N/A | P14: #N/A
A15: Glovis Luminous | C15: GLUM-60023/26-1 | D15: =IF(OR(ISNUMBER(SEARCH("Pre Delivery",E15)),ISNUMBER(SEARCH("Pre-Delivery",E15)),ISNUMBER(SEARCH("Predelivery",E15)),ISNUMBER(SEARCH("PD -",E15)),ISNUMBER(SEARCH("PD Lubes",E15))),"Pre-Delivery","") -> Pre-Delivery | E15: Pre Delivery - FLIR Camera | F15: Thermal Camera (FLIR) | H15: Spares | I15: Pending Delivery | J15: 46099 | L15: PCTC | M15: #N/A | N15: #N/A | O15: #N/A | P15: #N/A
A16: Glovis Luminous | C16: GLUM-60001/26-1 | D16: =IF(OR(ISNUMBER(SEARCH("Pre Delivery",E16)),ISNUMBER(SEARCH("Pre-Delivery",E16)),ISNUMBER(SEARCH("Predelivery",E16)),ISNUMBER(SEARCH("PD -",E16)),ISNUMBER(SEARCH("PD Lubes",E16))),"Pre-Delivery","") | E16: Shipyard Extra Owner supply - Captains Eye | F16: Navigation - Captains Eye | H16: Spares | I16: Pending Delivery | J16: 46037 | L16: PCTC | M16: #N/A | N16: #N/A | O16: #N/A | P16: #N/A
A17: Glovis Luminous | C17: GLUM-60017/26-1 | D17: =IF(OR(ISNUMBER(SEARCH("Pre Delivery",E17)),ISNUMBER(SEARCH("Pre-Delivery",E17)),ISNUMBER(SEARCH("Predelivery",E17)),ISNUMBER(SEARCH("PD -",E17)),ISNUMBER(SEARCH("PD Lubes",E17))),"Pre-Delivery","") | E17: Reliability Spares - Fire detection system | F17: Fire Detection System | H17: Spares | I17: Pending Delivery | J17: 46087 | L17: PCTC | M17: #N/A | N17: #N/A | O17: #N/A | P17: #N/A
A18: Glovis Luminous | C18: GLUM-60002/26-1 | D18: =IF(OR(ISNUMBER(SEARCH("Pre Delivery",E18)),ISNUMBER(SEARCH("Pre-Delivery",E18)),ISNUMBER(SEARCH("Predelivery",E18)),ISNUMBER(SEARCH("PD -",E18)),ISNUMBER(SEARCH("PD Lubes",E18))),"Pre-Delivery","") | E18: FS-KVH-GSI | F18: Communications - VSAT (KVH) | H18: Spares | I18: Pending Delivery | J18: 46048 | L18: PCTC | M18: #N/A | N18: #N/A | O18: #N/A | P18: #N/A
A19: Glovis Luminous | C19: GLUM-60022/26-1 | D19: =IF(OR(ISNUMBER(SEARCH("Pre Delivery",E19)),ISNUMBER(SEARCH("Pre-Delivery",E19)),ISNUMBER(SEARCH("Predelivery",E19)),ISNUMBER(SEARCH("PD -",E19)),ISNUMBER(SEARCH("PD Lubes",E19))),"Pre-Delivery","") -> Pre-Delivery | E19: Pre Delivery - Sample Cooler | F19: Sample Cooler | H19: Spares | I19: Pending Supplier Confirmation | J19: 46101 | L19: PCTC | M19: #N/A | N19: #N/A | O19: #N/A | P19: #N/A
A20: Glovis Luminous | C20: GLUM-60009/26-1 | D20: =IF(OR(ISNUMBER(SEARCH("Pre Delivery",E20)),ISNUMBER(SEARCH("Pre-Delivery",E20)),ISNUMBER(SEARCH("Predelivery",E20)),ISNUMBER(SEARCH("PD -",E20)),ISNUMBER(SEARCH("PD Lubes",E20))),"Pre-Delivery","") | E20: FS-ITBP CABLES | F20: IT Equipment - ITBP Cables | H20: Spares | I20: Pending Supplier Confirmation | J20: 46071 | L20: PCTC | M20: #N/A | N20: #N/A | O20: #N/A | P20: #N/A
A21: Glovis Luminous | C21: GLUM-60007/26-1 | D21: =IF(OR(ISNUMBER(SEARCH("Pre Delivery",E21)),ISNUMBER(SEARCH("Pre-Delivery",E21)),ISNUMBER(SEARCH("Predelivery",E21)),ISNUMBER(SEARCH("PD -",E21)),ISNUMBER(SEARCH("PD Lubes",E21))),"Pre-Delivery","") | E21: FS-LENOVO-Luminous | F21: IT Equipment - Computers (Lenovo) | H21: Spares | I21: Pending Delivery | J21: 46066 | L21: PCTC | M21: #N/A | N21: #N/A | O21: #N/A | P21: #N/A
... A27: Glovis Luminous | C27: GLUM-60005/26-1 | D27: =IF(OR(ISNUMBER(SEARCH("Pre Delivery",E27)),ISNUMBER(SEARCH("Pre-Delivery",E27)),ISNUMBER(SEARCH("Predelivery",E27)),ISNUMBER(SEARCH("PD -",E27)),ISNUMBER(SEARCH("PD Lubes",E27))),"Pre-Delivery","") | E27: SHIPYARD EXTRA ONWER SUPPLY - Abanaki Skimmers | F27: Oil Skimmers - Abanaki | H27: Spares | I27: Pending Supplier Confirmation | J27: 46065 | L27: PCTC | M27: #N/A | N27: #N/A | O27: #N/A | P27: #N/A
A28: Glovis Luminous | C28: GLUM-60014/26 | D28: =IF(OR(ISNUMBER(SEARCH("Pre Delivery",E28)),ISNUMBER(SEARCH("Pre-Delivery",E28)),ISNUMBER(SEARCH("Predelivery",E28)),ISNUMBER(SEARCH("PD -",E28)),ISNUMBER(SEARCH("PD Lubes",E28))),"Pre-Delivery","") | E28: Reliability Spares - PCTC-Seaspan - Boilers QUOT26012103 | F28: Boiler Spares | H28: Spares | I28: Pending Approval | J28: 46078 | K28: To be Approved | L28: PCTC | M28: #N/A | N28: #N/A | O28: #N/A | P28: #N/A
A29: Glovis Luminous | C29: GLUM-60025/26 | D29: =IF(OR(ISNUMBER(SEARCH("Pre Delivery",E29)),ISNUMBER(SEARCH("Pre-Delivery",E29)),ISNUMBER(SEARCH("Predelivery",E29)),ISNUMBER(SEARCH("PD -",E29)),ISNUMBER(SEARCH("PD Lubes",E29))),"Pre-Delivery","") | E29: Ultrasonic Cleaner | F29: Ultrasonic Cleaner | H29: Stores | I29: Pending Approval | K29: To be Approved | L29: PCTC | M29: #N/A | N29: #N/A | O29: #N/A | P29: #N/A
A30: Glovis Luminous | C30: GLUM-60026/26 | D30: =IF(OR(ISNUMBER(SEARCH("Pre Delivery",E30)),ISNUMBER(SEARCH("Pre-Delivery",E30)),ISNUMBER(SEARCH("Predelivery",E30)),ISNUMBER(SEARCH("PD -",E30)),ISNUMBER(SEARCH("PD Lubes",E30))),"Pre-Delivery","") | E30: OPA 90 KIT - 12-barrel kit | F30: OPA 90 Kit | H30: Stores | I30: Pending Approval | K30: To be Approved | L30: PCTC | M30: #N/A | N30: #N/A | O30: #N/A | P30: #N/A
A31: Glovis Luminous | C31: GLUM-60027/26 | D31: =IF(OR(ISNUMBER(SEARCH("Pre Delivery",E31)),ISNUMBER(SEARCH("Pre-Delivery",E31)),ISNUMBER(SEARCH("Predelivery",E31)),ISNUMBER(SEARCH("PD -",E31)),ISNUMBER(SEARCH("PD Lubes",E31))),"Pre-Delivery","") | E31: H.P machine - 2pcs (prefer Branded - Karcher/ KEW) | F31: High Pressure Washer | H31: Stores | I31: Pending Approval | K31: To be Approved | L31: PCTC | M31: #N/A | N31: #N/A | O31: #N/A | P31: #N/A
A32: Glovis Luminous | C32: GLUM-60028/26 | D32: =IF(OR(ISNUMBER(SEARCH("Pre Delivery",E32)),ISNUMBER(SEARCH("Pre-Delivery",E32)),ISNUMBER(SEARCH("Predelivery",E32)),ISNUMBER(SEARCH("PD -",E32)),ISNUMBER(SEARCH("PD Lubes",E32))),"Pre-Delivery","") | E32: Steam Splash Suit | F32: Steam Splash Suit | H32: Stores | I32: Pending Approval | K32: To be Approved | L32: PCTC | M32: #N/A | N32: #N/A | O32: #N/A | P32: #N/A
A33: Glovis Luminous | C33: GLUM-60033/26 | D33: =IF(OR(ISNUMBER(SEARCH("Pre Delivery",E33)),ISNUMBER(SEARCH("Pre-Delivery",E33)),ISNUMBER(SEARCH("Predelivery",E33)),ISNUMBER(SEARCH("PD -",E33)),ISNUMBER(SEARCH("PD Lubes",E33))),"Pre-Delivery","") | E33: Gas Meter | F33: Gas Meters | H33: Stores | L33: PCTC | M33: #N/A | N33: #N/A | O33: #N/A | P33: #N/A
A34: Glovis LightHouse | D34: =IF(OR(ISNUMBER(SEARCH("Pre Delivery",E34)),ISNUMBER(SEARCH("Pre-Delivery",E34)),ISNUMBER(SEARCH("Predelivery",E34)),ISNUMBER(SEARCH("PD -",E34)),ISNUMBER(SEARCH("PD Lubes",E34))),"Pre-Delivery","") | E34: Oily Water Separator | F34: Oily Water Separator | H34: Alfa Laval | L34: PCTC | M34: #N/A | N34: #N/A | O34: #N/A | P34: #N/A
A35: Glovis LightHouse | D35: =IF(OR(ISNUMBER(SEARCH("Pre Delivery",E35)),ISNUMBER(SEARCH("Pre-Delivery",E35)),ISNUMBER(SEARCH("Predelivery",E35)),ISNUMBER(SEARCH("PD -",E35)),ISNUMBER(SEARCH("PD Lubes",E35))),"Pre-Delivery","") | E35: BWTS Spares | F35: BWTS Spares | H35: Alfa Laval | L35: PCTC | M35: #N/A | N35: #N/A | O35: #N/A | P35: #N/A
A36: Glovis LightHouse | C36: GLIG-60094/26-1 | D36: =IF(OR(ISNUMBER(SEARCH("Pre Delivery",E36)),ISNUMBER(SEARCH("Pre-Delivery",E36)),ISNUMBER(SEARCH("Predelivery",E36)),ISNUMBER(SEARCH("PD -",E36)),ISNUMBER(SEARCH("PD Lubes",E36))),"Pre-Delivery","") | E36: EV Lance | F36: EV Lance | H36: Spares | L36: PCTC | M36: 1794590 | N36: JPY | O36: MOL Techno Trade Ltd | P36: Checking
A37: Glovis LightHouse | C37: GLIG-60034/26-1 | D37: =IF(OR(ISNUMBER(SEARCH("Pre Delivery",E37)),ISNUMBER(SEARCH("Pre-Delivery",E37)),ISNUMBER(SEARCH("Predelivery",E37)),ISNUMBER(SEARCH("PD -",E37)),ISNUMBER(SEARCH("PD Lubes",E37))),"Pre-Delivery","") | E37: Jonghap - PCTC Loose Fittings Procurement | F37: RO-RO Equipment - Loose Fittings | H37: Spares | L37: PCTC | M37: 486174 | N37: USD | O37: Jonghap Maritime Engineering Inc. | P37: Contracted
A38: Glovis LightHouse | C38: GLIG-60030/26-1 | D38: =IF(OR(ISNUMBER(SEARCH("Pre Delivery",E38)),ISNUMBER(SEARCH("Pre-Delivery",E38)),ISNUMBER(SEARCH("Predelivery",E38)),ISNUMBER(SEARCH("PD -",E38)),ISNUMBER(SEARCH("PD Lubes",E38))),"Pre-Delivery","") -> Pre-Delivery | E38: Pre Delivery Lubes Order# 3 (5714478288) | F38: Lubricants | H38: Lube Oil | L38: PCTC | M38: 305941 | N38: USD | O38: TotalEnergies Lubrifiants | P38: Contracted
A39: Glovis LightHouse | C39: GLIG-60021/26-1 | D39: =IF(OR(ISNUMBER(SEARCH("Pre Delivery",E39)),ISNUMBER(SEARCH("Pre-Delivery",E39)),ISNUMBER(SEARCH("Predelivery",E39)),ISNUMBER(SEARCH("PD -",E39)),ISNUMBER(SEARCH("PD Lubes",E39))),"Pre-Delivery","") | E39: FS-Interface-Light house | F39: IT Equipment - Interface / Integration | H39: Others | L39: PCTC | M39: 260191 | N39: HKD | O39: Interface Computer System Co. Ltd. | P39: Checking
A40: Glovis LightHouse | C40: GLIG-60005/26-1 | D40: =IF(OR(ISNUMBER(SEARCH("Pre Delivery",E40)),ISNUMBER(SEARCH("Pre-Delivery",E40)),ISNUMBER(SEARCH("Predelivery",E40)),ISNUMBER(SEARCH("PD -",E40)),ISNUMBER(SEARCH("PD Lubes",E40))),"Pre-Delivery","") | E40: Shipyard Extra Owner supply - Captains Eye | F40: Navigation - Captains Eye | H40: Spares | L40: PCTC | M40: 224200 | N40: USD | O40: Captain's Eye | P40: Contracted
A41: Glovis LightHouse | C41: GLIG-60079/26-1 | D41: =IF(OR(ISNUMBER(SEARCH("Pre Delivery",E41)),ISNUMBER(SEARCH("Pre-Delivery",E41)),ISNUMBER(SEARCH("Predelivery",E41)),ISNUMBER(SEARCH("PD -",E41)),ISNUMBER(SEARCH("PD Lubes",E41))),"Pre-Delivery","") | E41: Main Engine Spares | F41: Engine Spares - Main Engine | H41: Spares | L41: PCTC | M41: 215083 | N41: EUR | O41: MAN B and W Diesel-Copenhagen Denmark | P41: Checking
A42: Glovis LightHouse | C42: GLIG-60080/26-1 | D42: =IF(OR(ISNUMBER(SEARCH("Pre Delivery",E42)),ISNUMBER(SEARCH("Pre-Delivery",E42)),ISNUMBER(SEARCH("Predelivery",E42)),ISNUMBER(SEARCH("PD -",E42)),ISNUMBER(SEARCH("PD Lubes",E42))),"Pre-Delivery","") | E42: Aux. Engine Spares | F42: Engine Spares - Auxiliary Engine | H42: Spares | L42: PCTC | M42: 113839 | N42: EUR | O42: Wartsila Canada Inc. | P42: Checking
A43: Glovis LightHouse | D43: =IF(OR(ISNUMBER(SEARCH("Pre Delivery",E43)),ISNUMBER(SEARCH("Pre-Delivery",E43)),ISNUMBER(SEARCH("Predelivery",E43)),ISNUMBER(SEARCH("PD -",E43)),ISNUMBER(SEARCH("PD Lubes",E43))),"Pre-Delivery","") | E43: Sewage Traetment Plant | F43: Sewage Treatment Plant | H43: CSSC Nanjing | L43: PCTC | M43: #N/A | N43: #N/A | O43: #N/A | P43: #N/A
A44: Glovis LightHouse | D44: =IF(OR(ISNUMBER(SEARCH("Pre Delivery",E44)),ISNUMBER(SEARCH("Pre-Delivery",E44)),ISNUMBER(SEARCH("Predelivery",E44)),ISNUMBER(SEARCH("PD -",E44)),ISNUMBER(SEARCH("PD Lubes",E44))),"Pre-Delivery","") | E44: Sewage Discharge P/P | F44: Sewage Discharge Pump | H44: CSSC Nanjing | L44: PCTC | M44: #N/A | N44: #N/A | O44: #N/A | P44: #N/A
A45: Glovis LightHouse | C45: GLIG-60002/25-1 | D45: =IF(OR(ISNUMBER(SEARCH("Pre Delivery",E45)),ISNUMBER(SEARCH("Pre-Delivery",E45)),ISNUMBER(SEARCH("Predelivery",E45)),ISNUMBER(SEARCH("PD -",E45)),ISNUMBER(SEARCH("PD Lubes",E45))),"Pre-Delivery","") -> Pre-Delivery | E45: Pre-Delivery - Lubes | F45: Lubricants | H45: Lube Oil | L45: PCTC | M45: 83443 | N45: USD | O45: TotalEnergies Lubrifiants | P45: Contracted
...

Sheet Insights
B2: Goal: To identify suppliers for potential bulk discounts opportunities 1. Breakdown: Vessel Category > Category > Line items > Suppliers 2. Identify common items with key suppliers across vessel categories 3. Consolidate spend items with suppliers and highlight potential areas to seek further discounts
B10: Contract Status | C10: (Multiple Items)
B12: PO Values | C12: Projects
B13: Row Labels | C13: Glovis Lander | D13: Glovis LightHouse | E13: Glovis Link | F13: Glovis Logos | G13: Glovis Loyal | H13: Glovis Luminous | I13: (blank) | J13: Grand Total
B14: Spares | C14: 0 | D14: 1057357 | E14: 0 | F14: 0 | G14: 0 | H14: 0 | J14: 1057357
B15: Air driven HP Pump - For hydraulic nuts for M/E | D15: 0 | J15: 0
B16: #N/A | D16: 0 | J16: 0
B17: Alcometer | E17: 0 | J17: 0
B18: #N/A | E18: 0 | J18: 0
B19: Bosch GLM-50 or Laser Distance Measuring Tool | E19: 0 | J19: 0
B20: #N/A | E20: 0 | J20: 0
B21: Buyer Supply - 10,800 PCTC Citadel VHF/GPS and UHF ANTENNA system | D21: 39000 | J21: 39000
B22: West Nautical Pte Ltd | D22: 39000 | J22: 39000
B23: Citadel VHF/GPS and UHF ANTENNA system | C23: 0 | D23: 0 | J23: 0
B24: #N/A | C24: 0 | J24: 0
B25: #N/A | D25: 0 | J25: 0
B26: DF Tools | E26: 0 | J26: 0
B27: #N/A | E27: 0 | J27: 0
B28: Domestic refrigerators 200 litres for rec rooms to be added to stores supplies | E28: 0 | J28: 0
B29: #N/A | E29: 0 | J29: 0
B30: EV Lance | E30: 0 | J30: 0
B31: #N/A | E31: 0 | J31: 0
B32: FLIR ESPro and E6 Pro | G32: 0 | J32: 0
B33: #N/A | G33: 0 | J33: 0
B34: FS-ITBP -luminous | H34: 0 | J34: 0
B35: #N/A | H35: 0 | J35: 0
B36: FS-ITBP Additional Item | G36: 0 | H36: 0 | J36: 0
B37: #N/A | G37: 0 | H37: 0 | J37: 0
B38: FS-ITBP CABLES | G38: 0 | H38: 0 | J38: 0
B39: #N/A | G39: 0 | H39: 0 | J39: 0
B40: FS-ITBP MISC LAB KIT | G40: 0 | H40: 0 | J40: 0
B41: #N/A | G41: 0 | H41: 0 | J41: 0
B42: FS-KVH-GSI | H42: 0 | J42: 0
B43: #N/A | H43: 0 | J43: 0
B44: FS-LENOVO-Luminous | H44: 0 | J44: 0
B45: #N/A | H45: 0 | J45: 0
B46: FS-VLINK CABLE | G46: 0 | J46: 0
B47: #N/A | G47: 0 | J47: 0
B48: FS-X10-SILVERPEAK | H48: 0 | J48: 0
B49: #N/A | H49: 0 | J49: 0
...

Sheet 📊 Fleet Summary
A1: 🚢 Newbuild PO Summary
A2: Vessel names and shipyards pull automatically from each vessel sheet. All counts update live.
A4: Vessel Name | B4: Shipyard | C4: Not Created | D4: To Be Created | E4: Pending Approval | F4: Approved & Issued | G4: Pending Delivery | H4: Delivered | I4: Total POs | J4: % Issued | K4: % Delivered
A5: ='Glovis Lighthouse'!C2 -> Glovis Lighthouse | B5: ='Glovis Lighthouse'!C3 -> SWS - Shanghai Waigaoqiao Shipbuilding Co., Ltd. | C5: =COUNTIF('Glovis Lighthouse'!E35:E140,"Not Created") -> 25 | D5: =COUNTIF('Glovis Lighthouse'!E35:E73,"To Be Created") -> 0 | E5: =COUNTIF('Glovis Lighthouse'!E35:E73,"Pending Approval") -> 0 | F5: =COUNTIF('Glovis Lighthouse'!E35:E73,"Approved & Issued") -> 0 | G5: =COUNTIF('Glovis Lighthouse'!E35:E73,"Pending Delivery") -> 23 | H5: =COUNTIF('Glovis Lighthouse'!E35:E73,"Delivered") -> 3 | I5: =COUNTA('Glovis Lighthouse'!B35:B73) -> 39 | J5: =IF(I5>0,(F5+G5)/I5,0) -> 0.58974359 | K5: =IF(I5>0,H5/I5,0) -> 0.076923077
A6: ='Glovis Link'!C2 -> Glovis Link | B6: ='Glovis Link'!C3 -> SWS | C6: =COUNTIF('Glovis Link'!E11:E151,"Not Created") -> 1 | D6: =COUNTIF('Glovis Link'!E11:E113,"To Be Created") -> 0 | E6: =COUNTIF('Glovis Link'!E11:E113,"Pending Approval") -> 9 | F6: =COUNTIF('Glovis Link'!E11:E113,"Approved & Issued") -> 0 | G6: =COUNTIF('Glovis Link'!E11:E113,"Pending Delivery") -> 23 | H6: =COUNTIF('Glovis Link'!E11:E113,"Delivered") -> 0 | I6: =COUNTA('Glovis Link'!B11:B113) -> 39 | J6: =IF(I6>0,(F6+G6)/I6,0) -> 0.58974359 | K6: =IF(I6>0,H6/I6,0) -> 0
A7: ='Glovis Logos'!C2 -> Glovis Logos | B7: ='Glovis Logos'!C3 -> SWS | C7: =COUNTIF('Glovis Logos'!E11:E151,"Not Created") -> 0 | D7: =COUNTIF('Glovis Logos'!E11:E113,"To Be Created") -> 0 | E7: =COUNTIF('Glovis Logos'!E11:E113,"Pending Approval") -> 6 | F7: =COUNTIF('Glovis Logos'!E11:E113,"Approved & Issued") -> 0 | G7: =COUNTIF('Glovis Logos'!E11:E113,"Pending Delivery") -> 19 | H7: =COUNTIF('Glovis Logos'!E11:E113,"Delivered") -> 0 | I7: =COUNTA('Glovis Logos'!B11:B113) -> 31 | J7: =IF(I7>0,(F7+G7)/I7,0) -> 0.61290323 | K7: =IF(I7>0,H7/I7,0) -> 0
A8: ='Glovis Loyal'!C2 -> Glovis Loyal | B8: ='Glovis Loyal'!C3 -> SWS | C8: =COUNTIF('Glovis Loyal'!E11:E151,"Not Created") -> 0 | D8: =COUNTIF('Glovis Loyal'!E11:E111,"To Be Created") -> 0 | E8: =COUNTIF('Glovis Loyal'!E11:E111,"Pending Approval") -> 5 | F8: =COUNTIF('Glovis Loyal'!E11:E111,"Approved & Issued") -> 0 | G8: =COUNTIF('Glovis Loyal'!E11:E111,"Pending Delivery") -> 6 | H8: =COUNTIF('Glovis Loyal'!E11:E111,"Delivered") -> 0 | I8: =COUNTA('Glovis Loyal'!B11:B111) -> 29 | J8: =IF(I8>0,(F8+G8)/I8,0) -> 0.20689655 | K8: =IF(I8>0,H8/I8,0) -> 0
A9: ='Glovis Lander'!C2 -> Glovis Lander | B9: ='Glovis Lander'!C3 -> GSI: Guangzhou United International Shipping Agency Co., Ltd | C9: =COUNTIF('Glovis Lander'!F11:F150,"Not Created") -> 1 | D9: =COUNTIF('Glovis Lander'!F11:F110,"To Be Created") -> 0 | E9: =COUNTIF('Glovis Lander'!F11:F110,"Pending Approval") -> 4 | F9: =COUNTIF('Glovis Lander'!F11:F110,"Approved & Issued") -> 0 | G9: =COUNTIF('Glovis Lander'!F11:F110,"Pending Delivery") -> 30 | H9: =COUNTIF('Glovis Lander'!F11:F110,"Delivered") -> 6 | I9: =COUNTA('Glovis Lander'!B11:B110) -> 56 | J9: =IF(I9>0,(F9+G9)/I9,0) -> 0.53571429 | K9: =IF(I9>0,H9/I9,0) -> 0.10714286
A10: ='Glovis Luminous'!C2 -> 0 | B10: ='Glovis Luminous'!C3 -> 0 | C10: =COUNTIF('Glovis Luminous'!E11:E150,"Not Created") -> 0 | D10: =COUNTIF('Glovis Luminous'!E11:E110,"To Be Created") -> 0 | E10: =COUNTIF('Glovis Luminous'!E11:E110,"Pending Approval") -> 5 | F10: =COUNTIF('Glovis Luminous'!E11:E110,"Approved & Issued") -> 0 | G10: =COUNTIF('Glovis Luminous'!E11:E110,"Pending Delivery") -> 11 | H10: =COUNTIF('Glovis Luminous'!E11:E110,"Delivered") -> 0 | I10: =COUNTA('Glovis Luminous'!B11:B110) -> 28 | J10: =IF(I10>0,(F10+G10)/I10,0) -> 0.39285714 | K10: =IF(I10>0,H10/I10,0) -> 0
A11: ='Vessel 7'!C2 -> 0 | B11: ='Vessel 7'!C3 -> 0 | C11: =COUNTIF('Vessel 7'!E11:E150,"Not Created") -> 0 | D11: =COUNTIF('Vessel 7'!E11:E110,"To Be Created") -> 0 | E11: =COUNTIF('Vessel 7'!E11:E110,"Pending Approval") -> 0 | F11: =COUNTIF('Vessel 7'!E11:E110,"Approved & Issued") -> 0 | G11: =COUNTIF('Vessel 7'!E11:E110,"Pending Delivery") -> 0 | H11: =COUNTIF('Vessel 7'!E11:E110,"Delivered") -> 0 | I11: =COUNTA('Vessel 7'!B11:B110) -> 0 | J11: =IF(I11>0,(F11+G11)/I11,0) -> 0 | K11: =IF(I11>0,H11/I11,0) -> 0
A12: ='Vessel 8'!C2 -> 0 | B12: ='Vessel 8'!C3 -> 0 | C12: =COUNTIF('Vessel 8'!E11:E150,"Not Created") -> 0 | D12: =COUNTIF('Vessel 8'!E11:E110,"To Be Created") -> 0 | E12: =COUNTIF('Vessel 8'!E11:E110,"Pending Approval") -> 0 | F12: =COUNTIF('Vessel 8'!E11:E110,"Approved & Issued") -> 0 | G12: =COUNTIF('Vessel 8'!E11:E110,"Pending Delivery") -> 0 | H12: =COUNTIF('Vessel 8'!E11:E110,"Delivered") -> 0 | I12: =COUNTA('Vessel 8'!B11:B110) -> 0 | J12: =IF(I12>0,(F12+G12)/I12,0) -> 0 | K12: =IF(I12>0,H12/I12,0) -> 0
A13: FLEET TOTAL | C13: =SUM(C5:C12) -> 27 | D13: =SUM(D5:D12) -> 0 | E13: =SUM(E5:E12) -> 29 | F13: =SUM(F5:F12) -> 0 | G13: =SUM(G5:G12) -> 112 | H13: =SUM(H5:H12) -> 9 | I13: =SUM(I5:I12) -> 222 | J13: =IF(I13>0,(F13+G13)/I13,0) -> 0.5045045 | K13: =IF(I13>0,H13/I13,0) -> 0.040540541

Sheet Glovis Lander
A1: 🚢 Vessel Purchase Order Tracker
A2: Vessel Name: | C2: Glovis Lander | G2: ← e.g. Seaspan New York
A3: Shipyard: | C3: GSI: Guangzhou United International Shipping Agency Co., Ltd | G3: ← e.g. YZJ Shipyard
A4: Vessel Delivery Date: | C4: 46212 | E4: ← Enter date as: 01-Jun-2025
E5: PO Number | F5: PO Name | G5: Category | H5: Status | I5: PO Issue Date | J5: Req. Delivery Date | K5: Reason / Remarks | L5: Responsible | M5: Supplier Name | N5: Po Currency | O5: Po Value | P5: Contract Status
A6: Not Created | B6: To Be Created | C6: Pending Approval | E6: Approved & Issued | F6: Pending Delivery | G6: Delivered | I6: Total POs | J6: % Issued | K6: % Delivered
A7: =COUNTIF(F11:F110,"Not Created") -> 1 | B7: =COUNTIF(F11:F110,"To Be Created") -> 0 | C7: =COUNTIF(F11:F110,"Pending Approval") -> 4 | E7: =COUNTIF(F11:F110,"Approved & Issued") -> 0 | F7: =COUNTIF(F11:F110,"Pending Delivery") -> 30 | G7: =COUNTIF(F11:F110,"Delivered") -> 6 | I7: =COUNTA(B11:B110) -> 56 | J7: =IF(I7>0,(E7+F7)/I7,0) -> 0.53571429 | K7: =IF(I7>0,G7/I7,0) -> 0.10714286
A9: 📅 Date fields: Enter dates as DD-MMM-YYYY format (e.g. 15-Jan-2025). Columns F & G are date columns.
A10: S/N | B10: PO Number | C10: PO Name | E10: Category | F10: Status | G10: PO Issue Date | I10: Req. Delivery Date | J10: Reason / Remarks
A11: 1 | B11: GLAN-60031/26-1 | C11: Reliabiltiy Spares - Gas Detection System | E11: Spares | F11: Pending Delivery | G11: 06-03-2026 | J11: To advise Shipping Address
A12: 2 | B12: GLAN-60024/26-1 | C12: FS-ITBP MISC LAB KIT | E12: Others | F12: Pending Delivery | G12: 24-02-2026 | J12: IT Po
A13: 3 | B13: GLAN-60004/26-1 | C13: FS-VLINK-2411005 | E13: Others | F13: Pending Delivery | G13: 19-01-2026 | J13: IT Po
A14: 4 | B14: GLAN-60022/26-1 | C14: Shipyard Extra Buyer Supply - Hinas SVM SEASPAN 10.8K PCTC | E14: Spares | F14: Pending Delivery | G14: 17-02-2026 | J14: Status Awaited from Hinas
A15: 5 | B15: GLAN-60017/26-1 | C15: Pre Delivery - Garbage Compactor | E15: Spares | F15: Delivered | G15: 06-02-2026 | J15: As per POD from V-Link
A16: 6 | B16: GLAN-60007/26-1 | C16: FS-X10-LANDER | E16: Others | F16: Pending Delivery | G16: 21-01-2026 | J16: IT Po
A17: 7 | B17: GLAN-60002/26-1 | C17: Interface PO -24110005 | E17: Others | F17: Pending Delivery | G17: 14-01-2026 | J17: IT Po
A18: 8 | B18: GLAN-60012/26-1 | C18: Predelivery - Additional Grades | E18: Lube Oil | F18: Pending Delivery | G18: 23-01-2026 | J18: As per Delivery date Total Delivery date is pending
A19: 9 | B19: GLAN-60026/26-1 | C19: Predelivery Lubes - Order # 2 (5713853485) | E19: Lube Oil | F19: Delivered | G19: 02-03-2026 | J19: As per Email
A20: 10 | B20: GLAN-60032/26-1 | C20: Reliability Spares - Fire detection system | E20: Spares | F20: Pending Delivery | G20: 06-03-2026 | J20: To advise Shipping Address
A21: 11 | B21: GLAN-60023/26-1 | C21: FS-ITBP Additional Item | E21: Others | F21: Pending Delivery | G21: 19-02-2026 | J21: IT Po
A22: 12 | B22: GLAN-60033/26-1 | C22: Pre Delivery - LNG Bunkering Equipment | E22: Spares | F22: Pending Delivery | G22: 46100 | J22: Po Issued on Trelleborg
A23: 13 | B23: GLAN-60001/26-1 | C23: Shipyard Extra Owner supply - Captains Eye | E23: Spares | F23: Pending Delivery | G23: 15-01-2026 | J23: Awaiting status from Captain Eye
A24: 14 | B24: GLAN-60010/26-1 | C24: FS-SIHUI-lander | E24: Others | F24: Pending Delivery | G24: 26-01-2026 | J24: IT Po
A25: 15 | B25: GLAN-60025/26-1 | C25: Pre Delivery - Lubes Order# 3 (5715069528) | E25: Lube Oil | F25: Delivered | G25: 02-03-2026 | J25: As per Delivery Date on the Quotes
A26: 16 | B26: GLAN-60019/26-1 | C26: Pre Delivery - Spray Pipes | E26: Spares | F26: Delivered | G26: 06-02-2026 | J26: As per POD from V-Link
A27: 17 | B27: GLAN-60003/26-1 | C27: Pre Delivery - Additional Grade Copco Roto-XtendDuty | E27: Lube Oil | F27: Delivered | G27: 15-01-2026 | J27: As per POD from V-Link
A28: 18 | B28: GLAN-60011/26-1 | C28: Pre Delivery - Spray Pipes | E28: Lube Oil | F28: Delivered | G28: 01-02-2026 | J28: As per POD from V-Link
A29: 19 | B29: GLAN-60020/26-1 | C29: FS-LENOVO-Lander | E29: Others | F29: Pending Delivery | G29: 10-02-2026 | J29: IT Po
A30: 20 | B30: GLAN-60006/26-1 | C30: FS-ITBP -lander | E30: Others | F30: Pending Delivery | G30: 21-01-2026 | J30: IT Po
A31: 21 | B31: GLAN-60034/26-1 | C31: Pre Delivery - QCDC | E31: Spares | F31: Pending Delivery | G31: 06-03-2026 | J31: Po Issued on Trelleborg
A32: 22 | B32: GLAN-60015/26-1 | C32: FS-KVH-LANDER UPDATED | E32: Others | F32: Pending Delivery | G32: 23-01-2026 | J32: IT Po
A33: 23 | B33: GLAN-60030/26-1 | C33: PD - RSC Envirologic | E33: Spares | F33: Pending Delivery | J33: Qty to be Approved by Seyi'
A34: 24 | B34: GLAN-60005/26-1 | C34: FS-VLINK-Accessories | E34: Others | F34: Pending Delivery | G34: 21-01-2026 | J34: IT Po
A35: 25 | B35: GLAN-60008/26 | C35: FS -AST-LANDER | E35: Others | F35: Pending Delivery | G35: 20-01-2026 | J35: IT Po
A36: 26 | B36: GLAN-60009/26-1 | C36: FS -AST-LANDER | E36: Others | F36: Pending Delivery | G36: 21-01-2026 | J36: IT Po
A37: 27 | B37: GLAN-60016/26-1 | C37: FS-Interface-Lander | E37: Others | F37: Pending Delivery | G37: 29-01-2026 | J37: IT Po
A38: 28 | B38: GLAN-60028/26 | C38: Reliability Spares - PCTC-Seaspan - Boilers QUOT26012103 | E38: Spares | F38: Pending Approval | G38: 25-02-2026 | J38: Po to be Approved
A39: 29 | B39: GLAN-60018/26-1 | C39: SHIPYARD EXTRA OWNER SUPPLY- Abanaki Skimmers | E39: Spares | F39: Pending Delivery | G39: 12-02-2026 | J39: Frederic to advise the Po status
A40: 30 | B40: GLAN-60001/25-2 | C40: Lubricants - Pre Delivery | E40: Lube Oil | F40: Pending Delivery | G40: 25-11-2025 | J40: As per the Delivery date of OC
A41: 31 | B41: GLAN-60021/26-1 | C41: FS-ITBP CABLES | E41: Others | F41: Pending Delivery | G41: 10-02-2026 | J41: IT Po
...

Sheet Glovis Luminous
A1: 🚢 Vessel Purchase Order Tracker
A2: Vessel Name: | F2: ← e.g. Seaspan New York
A3: Shipyard: | F3: ← e.g. YZJ Shipyard
A4: Vessel Delivery Date: | D4: ← Enter date as: 01-Jun-2025
A6: Not Created | B6: To Be Created | C6: Pending Approval | D6: Approved & Issued | E6: Pending Delivery | F6: Delivered | G6: Total POs | H6: % Issued | I6: % Delivered
A7: =COUNTIF(E11:E110,"Not Created") -> 0 | B7: =COUNTIF(E11:E110,"To Be Created") -> 0 | C7: =COUNTIF(E11:E110,"Pending Approval") -> 5 | D7: =COUNTIF(E11:E110,"Approved & Issued") -> 0 | E7: =COUNTIF(E11:E110,"Pending Delivery") -> 11 | F7: =COUNTIF(E11:E110,"Delivered") -> 0 | G7: =COUNTA(B11:B110) -> 28 | H7: =IF(G7>0,(D7+E7)/G7,0) -> 0.39285714 | I7: =IF(G7>0,F7/G7,0) -> 0
A9: 📅 Date fields: Enter dates as DD-MMM-YYYY format (e.g. 15-Jan-2025). Columns F & G are date columns.
A10: S/N | B10: PO Number | C10: PO Name | D10: Category | E10: Status | F10: PO Issue Date | G10: Req. Delivery Date | H10: Reason / Remarks
A11: 1 | B11: GLUM-60015/26-1 | C11: PD - RSC Envirologic | E11: PO Created
A12: 2 | B12: GLUM-60003/26-1 | C12: FS-ITBP -luminous | E12: Pending Delivery | F12: 46055
A13: 3 | B13: GLUM-MVSP-60002/26-1 | C13: FS-X10-SILVERPEAK | E13: Pending Supplier Confirmation | F13: 46101
A14: 4 | B14: GLUM-60024/26-1 | C14: Service: LNG OPERATION MANUAL Development | E14: PO Created
A15: 5 | B15: GLUM-60006/26-1 | C15: Shipyard Extra Buyers Supply - Tripods and Spray Pipes | E15: Pending Delivery | F15: 46091
A16: 6 | B16: GLUM-60019/26-1 | C16: Shipyard Extra (buyer Supply) - QCDC -GSI | E16: Pending Supplier Confirmation | F16: 46101
A17: 7 | B17: GLUM-60016/26-1 | C17: Reliabiltiy Spares - Gas Detection System | E17: Pending Delivery | F17: 46087
A18: 8 | B18: GLUM-60008/26-1 | C18: Shipyard Extra Buyers Supply - Hinas SVM SEASPAN 10.8K PCTC | E18: Pending Supplier Confirmation | F18: 46070
A19: 9 | B19: GLUM-60010/26-1 | C19: FS-ITBP Additional Item | E19: Pending Delivery | F19: 46072
A20: 10 | B20: GLUM-60023/26-1 | C20: Pre Delivery - FLIR Camera | E20: Pending Delivery | F20: 46099
A21: 11 | B21: GLUM-60001/26-1 | C21: Shipyard Extra Owner supply - Captains Eye | E21: Pending Delivery | F21: 46037
A22: 12 | B22: GLUM-60017/26-1 | C22: Reliability Spares - Fire detection system | E22: Pending Delivery | F22: 46087
A23: 13 | B23: GLUM-60002/26-1 | C23: FS-KVH-GSI | E23: Pending Delivery | F23: 46048
A24: 14 | B24: GLUM-60022/26-1 | C24: Pre Delivery - Sample Cooler | E24: Pending Supplier Confirmation | F24: 46101
A25: 15 | B25: GLUM-60009/26-1 | C25: FS-ITBP CABLES | E25: Pending Supplier Confirmation | F25: 46071
A26: 16 | B26: GLUM-60007/26-1 | C26: FS-LENOVO-Luminous | E26: Pending Delivery | F26: 46066
... A32: 22 | B32: GLUM-60005/26-1 | C32: SHIPYARD EXTRA ONWER SUPPLY - Abanaki Skimmers | E32: Pending Supplier Confirmation | F32: 46065
A33: 23 | B33: GLUM-60014/26 | C33: Reliability Spares - PCTC-Seaspan - Boilers QUOT26012103 | E33: Pending Approval | F33: 46078 | H33: To be Approved
A34: 24 | B34: GLUM-60025/26 | C34: Ultrasonic Cleaner | D34: Stores | E34: Pending Approval | H34: To be Approved
A35: 25 | B35: GLUM-60026/26 | C35: OPA 90 KIT - 12-barrel kit | D35: Stores | E35: Pending Approval | H35: To be Approved
A36: 26 | B36: GLUM-60027/26 | C36: H.P machine - 2pcs (prefer Branded - Karcher/ KEW) | D36: Stores | E36: Pending Approval | H36: To be Approved
A37: 27 | B37: GLUM-60028/26 | C37: Steam Splash Suit | D37: Stores | E37: Pending Approval | H37: To be Approved
A38: 28 | B38: GLUM-60033/26 | C38: Gas Meter
A39: 29
A40: 30
A41: 31
A42: 32
A43: 33
A44: 34
A45: 35
A46: 36
A47: 37
...

Sheet Glovis Lighthouse
A1: 🚢 Vessel Purchase Order Tracker
A2: Vessel Name: | C2: Glovis Lighthouse | F2: ← e.g. Seaspan New York
A3: Shipyard: | C3: SWS - Shanghai Waigaoqiao Shipbuilding Co., Ltd. | F3: ← e.g. YZJ Shipyard
A4: Vessel Delivery Date: | C4: 46179 | D4: ← Enter date as: 01-Jun-2025
A6: Not Created | B6: To Be Created | C6: Pending Approval | D6: Approved & Issued | E6: Pending Delivery | F6: Delivered | G6: Total POs | H6: % Issued | I6: % Delivered
A7: 2 | B7: 0 | C7: 7 | D7: 0 | E7: 28 | F7: 3 | G7: 39 | H7: 0.71794872 | I7: 0.076923077
A9: 📅 Date fields: Enter dates as DD-MMM-YYYY format (e.g. 15-Jan-2025). Columns F & G are date columns.
A10: S/N | B10: PO Number | C10: PO Name | D10: Category | E10: Status | F10: PO Issue Date | G10: Req. Delivery Date | H10: Reason / Remarks | I10: Responsible | J10: Supplier Name | K10: Po Currency | L10: Po Value | M10: Contract Status | S10: Contracted
C11: Oily Water Separator | D11: Alfa Laval | H11: Alfa Laval | I11: Quote reqd for Marpol Spared | J11: #N/A | K11: #N/A | L11: #N/A | M11: Contracted | S11: Not Contracted
C12: BWTS Spares | D12: Alfa Laval | H12: Alfa Laval | I12: Quote reqd for Marpol Spared | J12: #N/A | K12: #N/A | L12: #N/A | S12: Invalidated
A13: 82 | B13: GLIG-60077/26-1 | C13: Crew Care | D13: Chemicals | E13: Pending Delivery | H13: Drew Delivery at Yard | J13: Drew Marine USA, Inc | K13: USD | L13: 3075.32 | S13: Under Review
A14: 81 | B14: GLIG-60075/26-1 | C14: Pre Delivery - Engineering Products & Kits (DREW) | D14: Chemicals | E14: Pending Delivery | H14: Drew Delivery at Yard | J14: Drew Marine USA, Inc | K14: USD | L14: 20708.78
A15: 79 | B15: GLIG-60071/26-1 | C15: Refrigerant Equipment | D15: Chemicals | E15: Pending Delivery | H15: Drew Delivery at Yard | J15: Drew Marine USA, Inc | K15: USD | L15: 7739.92
A16: 78 | B16: GLIG-60078/26-1 | C16: Pre Delivery - Welding Equipment | D16: Chemicals | E16: Pending Delivery | H16: Drew Delivery at Yard | J16: Drew Marine USA, Inc | K16: USD | L16: 30943.48
A17: 76 | B17: GLIG-60070/26-1 | C17: Gases | D17: Chemicals | E17: Pending Delivery | H17: Drew Delivery at Yard | J17: Drew Marine USA, Inc | K17: USD | L17: 5327.36
A18: 74 | B18: GLIG-60068/26-1 | C18: Pre Delivery - Treatment Chemical | D18: Chemicals | E18: Pending Delivery | H18: Drew Delivery at Yard | J18: Drew Marine USA, Inc | K18: USD | L18: 9265.52
A19: 75 | B19: GLIG-60045/26-1 | C19: Maintenance Chemicals | D19: Chemicals | E19: Pending Delivery | H19: Drew Delivery at Yard | J19: Drew Marine USA, Inc | K19: USD | L19: 5339.14
C20: Sewage Traetment Plant | D20: CSSC Nanjing | H20: CSSC Nanjing | I20: Quote reqd for Marpol Spared | J20: #N/A | K20: #N/A | L20: #N/A
C21: Sewage Discharge P/P | D21: CSSC Nanjing | H21: CSSC Nanjing | I21: Quote reqd for Marpol Spared | J21: #N/A | K21: #N/A | L21: #N/A
A22: 23 | B22: GLIG-60030/26-1 | C22: Pre Delivery Lubes Order# 3 (5714478288) | D22: Lube Oil | E22: Delivered | F22: 46083 | H22: Delivered | J22: TotalEnergies Lubrifiants | K22: USD | L22: 305941.12
A23: 14 | B23: GLIG-60002/25-1 | C23: Pre-Delivery - Lubes | D23: Lube Oil | E23: Delivered | F23: 45958 | G23: 46017 | H23: Order #5713665401 shud be delivered | J23: TotalEnergies Lubrifiants | K23: USD | L23: 83442.94
A24: 27 | B24: GLIG-60001/25-1 | C24: Lubricants - Pre Delivery | D24: Lube Oil | E24: Pending Delivery | F24: 45951 | H24: OC #5713475236 | J24: TotalEnergies Lubrifiants | K24: USD | L24: 51229.5
B25: GLIG-60096/26-1 | C25: Final Sailing Qty of Lubes | D25: Lube Oil | E25: Pending Delivery | H25: Po Issued on Total 2 Pcs Kits | J25: TotalEnergies Lubrifiants | K25: USD | L25: 30700
A26: 33 | B26: GLIG-60025/26-1 | C26: PD Lubes - VLSQ61941 - Kaeser Fluid Rotary S-46X | D26: Lube Oil | E26: Delivered | F26: 46083 | H26: Delivered | J26: Vessel Link Marine Supply & Service Ltd | K26: USD | L26: 4413.5
A27: 99 | C27: RSC Lube oil - qty / Total for Glovis Lighthouse | D27: Lube Oil | E27: Not Created | H27: Total Lube Oil for BT for Glovis Lighthouse | I27: Sahaya to create Po for BT Oil on Total Qty 1 Drum | J27: #N/A | K27: #N/A | L27: #N/A
A28: 36 | B28: GLIG-60008/26-1 | C28: AST PO | D28: Others | E28: Pending Delivery | F28: 46037 | H28: IT PO | J28: Applied Satellite Technology Systems US LLC (AST Americas) | K28: USD | L28: 5765.71
A29: 20 | B29: GLIG-60021/26-1 | C29: FS-Interface-Light house | D29: Others | E29: Pending Delivery | F29: 46051 | G29: 46081 | H29: IT PO | J29: Interface Computer System Co. Ltd. | K29: HKD | L29: 260190.71
A30: 32 | B30: GLIG-60003/26-1 | C30: Interface PO | D30: Others | E30: Pending Delivery | F30: 46030 | G30: 46081 | H30: IT PO | J30: Interface Computer System Co. Ltd. | K30: HKD | L30: 55710
B31: GLIG-MVSP-60003/26-1 | C31: FS-Interface MTA adapter | D31: Others | J31: Interface Computer System Co. Ltd. | K31: HKD | L31: 1911
A32: 5 | B32: GLIG-60023/26-1 | C32: FS-ITBP CABLES | D32: Others | E32: Pending Delivery | F32: 46063 | G32: 46081 | H32: IT PO | J32: IT Blueprint Solutions Consulting Inc | K32: USD | L32: 1101.24
A33: 3 | B33: GLIG-60022/26-1 | C33: FS-LENOVO-Lighthouse | D33: Others | E33: Pending Delivery | F33: 46063 | G33: 46081 | H33: IT PO | J33: IT Blueprint Solutions Consulting Inc | K33: CAD | L33: 49418.82
A34: 21 | B34: GLIG-60012/26-1 | C34: FS-ITBP -glovis lighthouse | D34: Others | E34: Pending Delivery | F34: 46041 | G34: 46081 | H34: IT PO | J34: IT Blueprint Solutions Consulting Inc | K34: USD | L34: 29715.77
A35: 22 | B35: GLIG-60029/26-1 | C35: FS-ITBP MISC LAB KIT | D35: Others | E35: Pending Delivery | F35: 46077 | G35: 46081 | H35: IT PO | J35: IT Blueprint Solutions Consulting Inc | K35: USD | L35: 200.91
A36: 38 | B36: GLIG-60028/26-1 | C36: FS-ITBP Additional Item | D36: Others | E36: Pending Delivery | F36: 46072 | G36: 46081 | H36: IT PO | J36: IT Blueprint Solutions Consulting Inc | K36: USD | L36: 1494.12
A37: 17 | B37: GLIG-60019/26-1 | C37: FS-KVH -LIGHTHOUSE UPDATED | D37: Others | E37: Pending Delivery | F37: 46045 | H37: IT PO | J37: KVH Industries Inc | K37: USD | L37: 6775
B38: GLIG-60097/26-1 | D38: Others | E38: Pending Delivery | H38: IT PO | J38: KVH Industries Inc | K38: USD | L38: 4040
A39: 11 | B39: GLIG-60017/26-1 | C39: FS-SIHUI | D39: Others | E39: Pending Delivery | F39: 46048 | G39: 46081 | H39: IT PO | J39: SIHUI MARINE CO LTD | K39: USD | L39: 20000
A40: 10 | B40: GLIG-60013/26-1 | C40: FS-VLINK-Accessories | D40: Others | E40: Pending Delivery | F40: 46043 | H40: IT PO | J40: Vessel Link Marine Supply & Service Ltd | K40: USD | L40: 168
A41: 2 | B41: GLIG-60010/26-1 | C41: FS-VLINK-H1610 | D41: Others | E41: Pending Delivery | F41: 46041 | G41: 46081 | H41: IT PO | J41: Vessel Link Marine Supply & Service Ltd | K41: USD | L41: 25285
A42: 30 | B42: GLIG-60027/26-1 | C42: FS-VLINK CABLE | D42: Others | E42: Pending Delivery | F42: 46064 | G42: 46081 | H42: IT PO | J42: Vessel Link Marine Supply & Service Ltd | K42: USD | L42: 63
...

Sheet Glovis Link
A1: 🚢 Vessel Purchase Order Tracker
A2: Vessel Name: | C2: Glovis Link | F2: ← e.g. Seaspan New York
A3: Shipyard: | C3: SWS | F3: ← e.g. YZJ Shipyard
A4: Vessel Delivery Date: | D4: ← Enter date as: 01-Jun-2025
A6: Not Created | B6: To Be Created | C6: Pending Approval | D6: Approved & Issued | E6: Pending Delivery | F6: Delivered | G6: Total POs | H6: % Issued | I6: % Delivered
A7: =COUNTIF(E11:E113,"Not Created") -> 1 | B7: =COUNTIF(E11:E113,"To Be Created") -> 0 | C7: =COUNTIF(E11:E113,"Pending Approval") -> 9 | D7: =COUNTIF(E11:E113,"Approved & Issued") -> 0 | E7: =COUNTIF(E11:E113,"Pending Delivery") -> 23 | F7: =COUNTIF(E11:E113,"Delivered") -> 0 | G7: =COUNTA(B11:B113) -> 39 | H7: =IF(G7>0,(D7+E7)/G7,0) -> 0.58974359 | I7: =IF(G7>0,F7/G7,0) -> 0
A9: 📅 Date fields: Enter dates as DD-MMM-YYYY format (e.g. 15-Jan-2025). Columns F & G are date columns.
A10: S/N | B10: PO Number | C10: PO Name | D10: Category | E10: Status | F10: PO Issue Date | G10: Req. Delivery Date | H10: Reason / Remarks
A11: 1 | B11: GLIN-60016/26-1 | C11: FS-VLINK CABLE | D11: Others | E11: Pending Delivery | F11: 11-02-2026 | G11: 46079 | H11: IT Po
A12: 2 | B12: GLIN-60019/26 | C12: Reliability Spares - PCTC-Seaspan - Boilers QUOT26012103_R00 | D12: Spares | E12: Pending Approval | F12: 25-02-2026 | H12: Po to be Approved
A13: 3 | B13: GLIN-60005/26-1 | C13: FS-ITBP -glovis link | D13: Others | E13: Pending Delivery | F13: 19-01-2026 | G13: 46079 | H13: IT Po
A14: 4 | B14: GLIN-60013/26-1 | C14: FS-ITBP CABLES | D14: Others | E14: Pending Delivery | F14: 10-02-2026 | G14: 46079 | H14: IT Po
A15: 5 | B15: GLIN-60009/26-1 | C15: FS-SIHUI-link | D15: Others | E15: Pending Delivery | F15: 26-01-2026 | G15: 46079 | H15: IT Po
A16: 6 | B16: GLIN-60012/26-1 | C16: FS-LENOVO-Link | D16: Others | E16: Pending Delivery | F16: 10-02-2026 | G16: 46079 | H16: IT Po
A17: 7 | B17: GLIN-60011/26-1 | C17: Shipyard Extra (Owner supply) - 10800 CEU LNG PCTC _x0013_ Consilium SMiG Integration | D17: Spares | E17: Pending Delivery | F17: 12-02-2026 | H17: It’s a Service, they shall advise the delivery dates shortly
A18: 8 | B18: GLIN-60004/26-1 | C18: FS-VLINK-H1612 | D18: Others | E18: Pending Delivery | F18: 19-01-2026 | G18: 46079 | H18: IT Po
A19: 9 | B19: GLIN-60017/26-1 | C19: FS-ITBP Additional Item | D19: Others | E19: Pending Delivery | F19: 19-02-2026 | G19: 46079 | H19: IT Po
A20: 10 | B20: GLIN-60020/26 | C20: Reliability Spares - PCTC-Seaspan - Boilers QUOT26012103 | E20: Not Created | F20: 25-02-2026 | H20: Duplicate
A21: 11 | B21: GLIN-60006/26-1 | C21: FS-VLINK-Accessories | D21: Others | E21: Pending Delivery | F21: 21-01-2026 | G21: 46079 | H21: IT Po
A22: 12 | B22: GLIN-60003/26-1 | C22: Interface PO-H1612 | D22: Others | E22: Pending Delivery | F22: 19-01-2026 | G22: 46079 | H22: IT Po
A23: 13 | B23: GLIN-60023/26-1 | C23: Reliabiltiy Spares - Gas Detection System | D23: Spares | E23: Pending Delivery | F23: 06-03-2026 | H23: To advise Shipping Address
A24: 14 | B24: GLIN-60007/26-1 | C24: FS-X10 | D24: Others | E24: Pending Delivery | F24: 46043 | G24: 46079 | H24: IT Po
A25: 15 | B25: GLIN-60015/26-1 | C25: Shipyard Extra Buyers supply - Hinas SVM SEASPAN 10.8K PCTC | D25: Spares | E25: Pending Delivery | F25: 17-02-2026 | H25: Seyi to advsie Email Id's of Avikus
A26: 16 | B26: GLIN-60010/26-1 | C26: FS-KVH-SWS | D26: Others | E26: Pending Delivery | F26: 26-01-2026 | G26: 46079 | H26: IT Po
A27: 17 | B27: GLIN-60008/26-1 | C27: FS -AST-LINK | D27: Others | E27: Pending Delivery | F27: 21-01-2026 | G27: 46079 | H27: IT Po
A28: 18 | B28: GLIN-60002/26-1 | C28: Predelivery - Visga 46 5715010143 | D28: Lube Oil | E28: Pending Delivery | F28: 19-02-2026 | G28: 46127 | H28: Awaiting Delivery
A29: 19 | B29: GLIN-60024/26-1 | C29: Reliability Spares - Fire detection system | D29: Spares | E29: Pending Delivery | F29: 06-03-2026 | H29: To advise Shipping Address
A30: 20 | B30: GLIN-60021/26 | C30: FS-ITBP-LICENSES | D30: Others | E30: Pending Delivery | F30: 25-02-2026 | G30: 46079 | H30: IT Po
A31: 21 | B31: GLIN-60025/26-1 | C31: FS-VLINK-Starlink Accessories | D31: Others | E31: Pending Delivery | F31: 46086 | G31: 46079 | H31: IT Po
A32: 22 | B32: GLIN-60026/26-1 | C32: SHIPYARD EXTRA OWNER SUPPLY- Abanaki Skimmers | D32: Spares | E32: Pending Approval | F32: 46091 | H32: Po shared with supplier, to be approved
A33: 23 | B33: GLIN-60018/26-1 | C33: FS-ITBP MISC LAB KIT | D33: Others | E33: Pending Delivery | F33: 24-02-2026 | G33: 46079 | H33: IT Po
A34: 24 | B34: GLIN-60022/26-1 | C34: PD - RSC Envirologic | D34: Spares | E34: Pending Delivery | H34: Seyi to advise exact Qty
A35: 25 | B35: GLIN-60014/26-2 | C35: Reliability Spares - 10,8K CEU SWS - GVT- Eltronic | D35: Spares | E35: Pending Approval | F35: 46112 | H35: Po to be Approved
A36: 26 | B36: GLIN-60033/26-1 | C36: LNG OPERATION MANUAL Development
A37: 27 | C37: Citadel VHF/GPS and UHF ANTENNA system | H37: Po 000030180277 Dummy Po raised as Vendor not enlisted in Jibe
A38: 28 | C38: PCTC Loose Fittings Procurement | H38: Vendor to be enlisted in database
A39: 29 | C39: Buyer Supply - 10,800 PCTC Citadel VHF/GPS and UHF ANTENNA system | H39: Dummy Po shared awaiting vendor to be enlisted
A40: 30 | B40: GLIN-60001/26 | C40: Shipyard Extra Owner supply - Captains Eye | H40: To check with BG as unable to see this Po
A41: 31 | B41: GLIN-60026/26-1 | C41: SHIPYARD EXTRA OWNER SUPPLY- Abanaki Skimmers | D41: Spares | E41: Pending Supplier Confirmation | F41: 46091 | H41: Po to be created however shared with Hermont
A42: 32 | B42: GLIN-60027/26-1 | C42: Pre Delivery - Garbage Compactor | E42: Pending Delivery | F42: 46094 | H42: Po to be Approved by VM
...

Sheet Glovis Logos
A1: 🚢 Vessel Purchase Order Tracker
A2: Vessel Name: | C2: Glovis Logos | F2: ← e.g. Seaspan New York
A3: Shipyard: | C3: SWS | F3: ← e.g. YZJ Shipyard
A4: Vessel Delivery Date: | D4: ← Enter date as: 01-Jun-2025
A6: Not Created | B6: To Be Created | C6: Pending Approval | D6: Approved & Issued | E6: Pending Delivery | F6: Delivered | G6: Total POs | H6: % Issued | I6: % Delivered
A7: =COUNTIF(E11:E113,"Not Created") -> 0 | B7: =COUNTIF(E11:E113,"To Be Created") -> 0 | C7: =COUNTIF(E11:E113,"Pending Approval") -> 6 | D7: =COUNTIF(E11:E113,"Approved & Issued") -> 0 | E7: =COUNTIF(E11:E113,"Pending Delivery") -> 19 | F7: =COUNTIF(E11:E113,"Delivered") -> 0 | G7: =COUNTA(B11:B113) -> 31 | H7: =IF(G7>0,(D7+E7)/G7,0) -> 0.61290323 | I7: =IF(G7>0,F7/G7,0) -> 0
A9: 📅 Date fields: Enter dates as DD-MMM-YYYY format (e.g. 15-Jan-2025). Columns F & G are date columns.
A10: S/N | B10: PO Number | C10: PO Name | D10: Category | E10: Status | F10: PO Issue Date | G10: Req. Delivery Date | H10: Reason / Remarks
A11: 17 | B11: GLOG-60001/26-1 | C11: Shipyard Extra Owner supply - Captains Eye | D11: Spares | E11: Pending Delivery | F11: 15-01-2026 | H11: Awaiting Readiness
A12: 13 | B12: GLOG-60002/26-1 | C12: FS-KVH-SWS-LOGOS | D12: Others | E12: Pending Delivery | F12: 26-01-2026 | H12: IT Po
A13: 12 | B13: GLOG-60003/26 | C13: FS-AST-SAMPLE | D13: Others | E13: Pending Delivery | F13: 26-01-2026 | H13: IT Po
A14: 4 | B14: GLOG-60005/26-1 | C14: FS-AST-LOGOS | D14: Others | E14: Pending Delivery | F14: 27-01-2026 | G14: 46079 | H14: IT Po
A15: 11 | B15: GLOG-60006/26-1 | C15: FS-ITBP -LOGOS | D15: Others | E15: Pending Delivery | F15: 27-01-2026 | H15: IT Po
A16: 9 | B16: GLOG-60007/26-1 | C16: Shipyard Extra (owner supply) 10800 CEU LNG PCTC _x0013_ Consilium SMiG Integration | D16: Spares | E16: Pending Delivery | F16: 12-02-2026 | H16: Awaiting Readiness
A17: 3 | B17: GLOG-60008/26-1 | C17: FS-LENOVO-Logos | D17: Others | E17: Pending Delivery | F17: 11-02-2026 | G17: 46079 | H17: IT Po
A18: 8 | B18: GLOG-60009/26-1 | C18: Reliability Spares - 10,8K CEU SWS - GVT- Eltronic | D18: Spares | E18: Pending Delivery | F18: 03-03-2026 | H18: Awaiting Readiness
A19: 1 | B19: GLOG-60010/26-1 | C19: Shipyard Extra Buyers Supply - Hinas SVM SEASPAN 10.8K PCTC | D19: Spares | E19: Pending Delivery | F19: 17-02-2026 | H19: Seyi to advsie Email Id's of Avikus
A20: 5 | B20: GLOG-60011/26-1 | C20: FS-VLINK CABLE | D20: Others | E20: Pending Delivery | F20: 11-02-2026 | G20: 46079 | H20: IT Po
A21: 14 | B21: GLOG-60012/26-1 | C21: FS-ITBP CABLES | D21: Others | E21: Pending Delivery | F21: 18-02-2026 | H21: IT Po
A22: 15 | B22: GLOG-60013/26-1 | C22: FS-ITBP Additional Item | D22: Others | E22: Pending Delivery | F22: 19-02-2026 | H22: IT Po
A23: 10 | B23: GLOG-60014/26-1 | C23: FS-ITBP MISC LAB KIT | D23: Others | E23: Pending Delivery | F23: 24-02-2026 | H23: IT Po
A24: 18 | B24: GLOG-60016/26 | C24: Reliability Spares - PCTC-Seaspan - Boilers QUOT26012103 | D24: Spares | E24: Pending Approval | F24: 25-02-2026 | H24: Po to be Approved
A25: 6 | B25: GLOG-60017/26-1 | C25: PD - RSC Envirologic | D25: Spares | E25: Pending Delivery | H25: Seyi to advise Qty
A26: 16 | B26: GLOG-60018/26-1 | C26: Reliabiltiy Spares - Gas Detection System | D26: Spares | E26: Pending Delivery | F26: 06-03-2026 | H26: To advise Shipping Address
A27: 7 | B27: GLOG-60019/26-1 | C27: Reliability Spares - Fire detection system | D27: Spares | E27: Pending Delivery | F27: 06-03-2026 | H27: To advise Shipping Instructions
A28: 2 | B28: GLOG-60020/26-1 | C28: SHIPYARD EXTRA OWNER SUPPLY- Abanaki Skimmers | D28: Spares | E28: Pending Delivery | F28: 46091 | H28: Po shared with supplier, to be approved
B29: GLOG-60020/26-1 | C29: SHIPYARD EXTRA OWNER SUPPLY- Abanaki Skimmers | D29: Spares | E29: Pending Supplier Confirmation | F29: 46091 | H29: Po to be created however shared to Supplier
B30: GLOG-60021/26-1 | C30: Pre Delivery - Garbage Compactor | D30: Spares | E30: Pending Delivery | F30: 46094 | H30: Po to be Approved by VM
A31: 49 | B31: GLOG-60022/26-1 | C31: Pre Delivery - Cryogenic PPE | D31: Stores | E31: Pending Supplier Confirmation | F31: 46101 | H31: Po to be Approved
A32: 61 | B32: GLOG-60024/26-1 | C32: Pre Delivery - Sample Cooler | D32: Spares | E32: Pending Approval | F32: 46101 | H32: Qty 2 Pcs to be Approved
A33: 68 | B33: GLOG-60025/26-1 | C33: Reliability - Donghwa Spares for BOG Compressor | D33: Spares | E33: Pending Supplier Confirmation | F33: 46111 | H33: To be Approved
A34: 47 | B34: GLOG-60026/26-1 | C34: FLIR ESPro and E6 Pro | D34: Stores | E34: Pending Delivery | H34: Po Issued to V-Link
B35: GLOG-60027/26-1 | C35: Service: LNG OPERATION MANUAL Development
A36: 19 | C36: Citadel VHF/GPS and UHF ANTENNA system | H36: Po 000030180276 Dummy Po raised as Vendor not enlisted in Jibe
A37: 20 | C37: PCTC Loose Fittings Procurement | H37: Vendor to be enlisted in database
A38: 21 | C38: Buyer Supply - 10,800 PCTC Citadel VHF/GPS and UHF ANTENNA system | H38: Dummy Po 000030180276 created as Vendor not in Jibe
A39: 22 | C39: Impa Stores Stationery
A40: 23 | C40: Impa Stores - SOPEP
A41: 24 | C41: Impa Stores - Deck
A42: 25 | C42: Impa Stores - Bridge
...

Sheet Glovis Loyal
A1: 🚢 Vessel Purchase Order Tracker
A2: Vessel Name: | C2: Glovis Loyal | F2: ← e.g. Seaspan New York
A3: Shipyard: | C3: SWS | F3: ← e.g. YZJ Shipyard
A4: Vessel Delivery Date: | D4: ← Enter date as: 01-Jun-2025
A6: Not Created | B6: To Be Created | C6: Pending Approval | D6: Approved & Issued | E6: Pending Delivery | F6: Delivered | G6: Total POs | H6: % Issued | I6: % Delivered
A7: =COUNTIF(E11:E111,"Not Created") -> 0 | B7: =COUNTIF(E11:E111,"To Be Created") -> 0 | C7: =COUNTIF(E11:E111,"Pending Approval") -> 5 | D7: =COUNTIF(E11:E111,"Approved & Issued") -> 0 | E7: =COUNTIF(E11:E111,"Pending Delivery") -> 6 | F7: =COUNTIF(E11:E111,"Delivered") -> 0 | G7: =COUNTA(B11:B111) -> 29 | H7: =IF(G7>0,(D7+E7)/G7,0) -> 0.20689655 | I7: =IF(G7>0,F7/G7,0) -> 0
A9: 📅 Date fields: Enter dates as DD-MMM-YYYY format (e.g. 15-Jan-2025). Columns F & G are date columns.
A10: S/N | B10: PO Number | C10: PO Name | D10: Category | E10: Status | F10: PO Issue Date | G10: Req. Delivery Date | H10: Reason / Remarks
A11: 6 | B11: GLOY-60001/26-1 | C11: Shipyard Extra Owner supply - Captains Eye | F11: 15-01-2026
A12: 2 | B12: GLOY-60002/26-1 | C12: FS-KVH-SWS-LOYAL | D12: Others | E12: Pending Delivery | F12: 26-01-2026 | H12: IT Po
A13: 7 | B13: GLOY-60004/26-1 | C13: FS-AST-LOYOL | F13: 27-01-2026
A14: 8 | B14: GLOY-60005/26-1 | C14: FS-ITBP -LOYAL | F14: 27-01-2026
A15: 9 | B15: GLOY-60006/26-1 | C15: SHIPYARD EXTRA OWNER SUPLPY - 10800 CEU LNG PCTC _x0013_ Consilium SMiG Integration | F15: 12-02-2026
A16: 13 | B16: GLOY-60007/26-1 | C16: FS-LENOVO-Loyal | F16: 13-02-2026
A17: 16 | B17: GLOY-60008/26-1 | C17: Reliability Spares - 10,8K CEU SWS - GVT- Eltronic | F17: 03-03-2026
A18: 5 | B18: GLOY-60009/26-1 | C18: Shipyard Extra Buyers Supply - Hinas SVM SEASPAN 10.8K PCTC | D18: Spares | E18: Pending Delivery | F18: 17-02-2026 | H18: Seyi to advsie Email Id's of Avikus
A19: 12 | B19: GLOY-60010/26-1 | C19: FS-VLINK CABLE | F19: 11-02-2026
A20: 14 | B20: GLOY-60012/26-1 | C20: FS-ITBP CABLES | F20: 18-02-2026
A21: 10 | B21: GLOY-60013/26-1 | C21: FS-ITBP Additional Item | F21: 19-02-2026
A22: 1 | B22: GLOY-60014/26-1 | C22: FS-ITBP MISC LAB KIT | D22: Others | E22: Pending Delivery | F22: 24-02-2026 | H22: IT Po
A23: 3 | B23: GLOY-60016/26 | C23: Reliability Spares - PCTC-Seaspan - Boilers QUOT26012103 | D23: Spares | E23: Pending Approval | F23: 25-02-2026 | H23: Po to be Approved
A24: 11 | B24: GLOY-60017/26-1 | C24: PD - RSC Envirologic
A25: 17 | B25: GLOY-60018/26-1 | C25: Reliabiltiy Spares - Gas Detection System | F25: 06-03-2026
A26: 4 | B26: GLOY-60019/26-1 | C26: Reliability Spares - Fire detection system | D26: Spares | E26: Pending Delivery | F26: 06-03-2026 | H26: To advise Shipping Instructions
A27: 15 | B27: GLOY-60020/26-1 | C27: SHIPYARD EXTRA OWNER SUPPLY- Abanaki Skimmers | D27: Spares | E27: Pending Supplier Confirmation | F27: 46091 | H27: Po to be created however shared to Supplier
A28: 18 | B28: GLOY-60021/26-1 | C28: Pre Delivery - Garbage Compactor | D28: Spares | E28: Pending Delivery | F28: 46094 | H28: To be approved by VM
A29: 46 | B29: GLOY-60022/26-1 | C29: Pre Delivery - Cryogenic PPE | D29: Stores | E29: Pending Supplier Confirmation | F29: 46101 | H29: Po to be Approved
A30: 58 | B30: GLOY-60024/26-1 | C30: Pre Delivery - Sample Cooler | D30: Spares | E30: Pending Supplier Confirmation | F30: 46101 | H30: Qty 2 Pcs
A31: 65 | B31: GLOY-60025/26-1 | C31: Reliability - Donghwa Spares for BOG Compressor | D31: Spares | E31: Pending Supplier Confirmation | F31: 46111 | H31: To be Approved
A32: 44 | B32: GLOY-60026/26-1 | C32: FLIR ESPro and E6 Pro | D32: Stores | E32: Pending Delivery | H32: Po issued on V-Link
B33: GLOY-60027/26-1 | C33: Service: LNG OPERATION MANUAL Development
A34: 19 | C34: Impa Stores Stationery
A35: 20 | C35: Impa Stores - SOPEP
A36: 21 | C36: Impa Stores - Deck
A37: 22 | C37: Impa Stores - Bridge
A38: 23 | C38: Impa Stores - Gym
A39: 24 | C39: Impa Stores - Crew
A40: 25 | C40: Impa Stores - FFE
A41: 26 | C41: Impa Stores - Company Stationery
A42: 27 | C42: Impa Stores - BA Compressor
...

Sheet tbc_project 2

Sheet Vessel 7
A1: 🚢 Vessel Purchase Order Tracker
A2: Vessel Name: | F2: ← e.g. Seaspan New York
A3: Shipyard: | F3: ← e.g. YZJ Shipyard
A4: Vessel Delivery Date: | D4: ← Enter date as: 01-Jun-2025
A6: Not Created | B6: To Be Created | C6: Pending Approval | D6: Approved & Issued | E6: Pending Delivery | F6: Delivered | G6: Total POs | H6: % Issued | I6: % Delivered
A7: =COUNTIF(E11:E110,"Not Created") -> 0 | B7: =COUNTIF(E11:E110,"To Be Created") -> 0 | C7: =COUNTIF(E11:E110,"Pending Approval") -> 0 | D7: =COUNTIF(E11:E110,"Approved & Issued") -> 0 | E7: =COUNTIF(E11:E110,"Pending Delivery") -> 0 | F7: =COUNTIF(E11:E110,"Delivered") -> 0 | G7: =COUNTA(B11:B110) -> 0 | H7: =IF(G7>0,(D7+E7)/G7,0) -> 0 | I7: =IF(G7>0,F7/G7,0) -> 0
A9: 📅 Date fields: Enter dates as DD-MMM-YYYY format (e.g. 15-Jan-2025). Columns F & G are date columns.
A10: S/N | B10: PO Number | C10: PO Name | D10: Category | E10: Status | F10: PO Issue Date | G10: Req. Delivery Date | H10: Reason / Remarks
A11: 1
A12: 2
A13: 3
A14: 4
A15: 5
A16: 6
A17: 7
A18: 8
A19: 9
A20: 10
A21: 11
A22: 12
... A110: 100

Sheet Vessel 8
A1: 🚢 Vessel Purchase Order Tracker
A2: Vessel Name: | F2: ← e.g. Seaspan New York
A3: Shipyard: | F3: ← e.g. YZJ Shipyard
A4: Vessel Delivery Date: | D4: ← Enter date as: 01-Jun-2025
A6: Not Created | B6: To Be Created | C6: Pending Approval | D6: Approved & Issued | E6: Pending Delivery | F6: Delivered | G6: Total POs | H6: % Issued | I6: % Delivered
A7: =COUNTIF(E11:E110,"Not Created") -> 0 | B7: =COUNTIF(E11:E110,"To Be Created") -> 0 | C7: =COUNTIF(E11:E110,"Pending Approval") -> 0 | D7: =COUNTIF(E11:E110,"Approved & Issued") -> 0 | E7: =COUNTIF(E11:E110,"Pending Delivery") -> 0 | F7: =COUNTIF(E11:E110,"Delivered") -> 0 | G7: =COUNTA(B11:B110) -> 0 | H7: =IF(G7>0,(D7+E7)/G7,0) -> 0 | I7: =IF(G7>0,F7/G7,0) -> 0
A9: 📅 Date fields: Enter dates as DD-MMM-YYYY format (e.g. 15-Jan-2025). Columns F & G are date columns.
A10: S/N | B10: PO Number | C10: PO Name | D10: Category | E10: Status | F10: PO Issue Date | G10: Req. Delivery Date | H10: Reason / Remarks
A11: 1
A12: 2
A13: 3
A14: 4
A15: 5
A16: 6
A17: 7
A18: 8
A19: 9
A20: 10
A21: 11
A22: 12
... A110: 100
